INFO:     Will watch for changes in these directories: ['/home/workspace']
INFO:     Uvicorn running on http://0.0.0.0:8000 (Press CTRL+C to quit)
INFO:     Started reloader process [560] using StatReload
INFO:     Started server process [562]
INFO:     Waiting for application startup.
INFO:     Application startup complete.
INFO:     172.20.0.1:34880 - "HEAD / HTTP/1.1" 405 Method Not Allowed
INFO:     172.20.0.1:53034 - "GET /hotels?max_price=800&limit=12 HTTP/1.1" 500 Internal Server Error
ERROR:    Exception in ASGI application
Traceback (most recent call last):
  File "/usr/local/lib/python3.13/site-packages/uvicorn/protocols/http/h11_impl.py", line 408, in run_asgi
    result = await app(  # type: ignore[func-returns-value]
             ^^^^^^^^^^^^^^^^^^^^^^^^^^^^^^^^^^^^^^^^^^^^^^
        self.scope, self.receive, self.send
        ^^^^^^^^^^^^^^^^^^^^^^^^^^^^^^^^^^^
    )
    ^
  File "/usr/local/lib/python3.13/site-packages/uvicorn/middleware/proxy_headers.py", line 84, in __call__
    return await self.app(scope, receive, send)
           ^^^^^^^^^^^^^^^^^^^^^^^^^^^^^^^^^^^^
  File "/usr/local/lib/python3.13/site-packages/fastapi/applications.py", line 1106, in __call__
    await super().__call__(scope, receive, send)
  File "/usr/local/lib/python3.13/site-packages/starlette/applications.py", line 122, in __call__
    await self.middleware_stack(scope, receive, send)
  File "/usr/local/lib/python3.13/site-packages/starlette/middleware/errors.py", line 184, in __call__
    raise exc
  File "/usr/local/lib/python3.13/site-packages/starlette/middleware/errors.py", line 162, in __call__
    await self.app(scope, receive, _send)
  File "/usr/local/lib/python3.13/site-packages/starlette/middleware/cors.py", line 91, in __call__
    await self.simple_response(scope, receive, send, request_headers=headers)
  File "/usr/local/lib/python3.13/site-packages/starlette/middleware/cors.py", line 146, in simple_response
    await self.app(scope, receive, send)
  File "/usr/local/lib/python3.13/site-packages/starlette/middleware/exceptions.py", line 79, in __call__
    raise exc
  File "/usr/local/lib/python3.13/site-packages/starlette/middleware/exceptions.py", line 68, in __call__
    await self.app(scope, receive, sender)
  File "/usr/local/lib/python3.13/site-packages/fastapi/middleware/asyncexitstack.py", line 20, in __call__
    raise e
  File "/usr/local/lib/python3.13/site-packages/fastapi/middleware/asyncexitstack.py", line 17, in __call__
    await self.app(scope, receive, send)
  File "/usr/local/lib/python3.13/site-packages/starlette/routing.py", line 718, in __call__
    await route.handle(scope, receive, send)
  File "/usr/local/lib/python3.13/site-packages/starlette/routing.py", line 276, in handle
    await self.app(scope, receive, send)
  File "/usr/local/lib/python3.13/site-packages/starlette/routing.py", line 66, in app
    response = await func(request)
               ^^^^^^^^^^^^^^^^^^^
  File "/usr/local/lib/python3.13/site-packages/fastapi/routing.py", line 274, in app
    raw_response = await run_endpoint_function(
                   ^^^^^^^^^^^^^^^^^^^^^^^^^^^^
        dependant=dependant, values=values, is_coroutine=is_coroutine
        ^^^^^^^^^^^^^^^^^^^^^^^^^^^^^^^^^^^^^^^^^^^^^^^^^^^^^^^^^^^^^
    )
    ^
  File "/usr/local/lib/python3.13/site-packages/fastapi/routing.py", line 193, in run_endpoint_function
    return await run_in_threadpool(dependant.call, **values)
           ^^^^^^^^^^^^^^^^^^^^^^^^^^^^^^^^^^^^^^^^^^^^^^^^^
  File "/usr/local/lib/python3.13/site-packages/starlette/concurrency.py", line 41, in run_in_threadpool
    return await anyio.to_thread.run_sync(func, *args)
           ^^^^^^^^^^^^^^^^^^^^^^^^^^^^^^^^^^^^^^^^^^^
  File "/usr/local/lib/python3.13/site-packages/anyio/to_thread.py", line 33, in run_sync
    return await get_asynclib().run_sync_in_worker_thread(
           ^^^^^^^^^^^^^^^^^^^^^^^^^^^^^^^^^^^^^^^^^^^^^^^
        func, *args, cancellable=cancellable, limiter=limiter
        ^^^^^^^^^^^^^^^^^^^^^^^^^^^^^^^^^^^^^^^^^^^^^^^^^^^^^
    )
    ^
  File "/usr/local/lib/python3.13/site-packages/anyio/_backends/_asyncio.py", line 877, in run_sync_in_worker_thread
    return await future
           ^^^^^^^^^^^^
  File "/usr/local/lib/python3.13/site-packages/anyio/_backends/_asyncio.py", line 807, in run
    result = context.run(func, *args)
  File "/home/workspace/main.py", line 155, in list_hotels
    _ensure_seed_hotels()
    ~~~~~~~~~~~~~~~~~~~^^
  File "/home/workspace/main.py", line 145, in _ensure_seed_hotels
    create_document("hotel", h)
    ~~~~~~~~~~~~~~~^^^^^^^^^^^^
  File "/home/workspace/database.py", line 43, in create_document
    result = db[collection_name].insert_one(data_dict)
  File "/usr/local/lib/python3.13/site-packages/pymongo/collection.py", line 669, in insert_one
    self._insert_one(
    ~~~~~~~~~~~~~~~~^
        document,
        ^^^^^^^^^
    ...<5 lines>...
        comment=comment,
        ^^^^^^^^^^^^^^^^
    ),
    ^
  File "/usr/local/lib/python3.13/site-packages/pymongo/collection.py", line 609, in _insert_one
    self.__database.client._retryable_write(acknowledged, _insert_command, session)
    ~~~~~~~~~~~~~~~~~~~~~~~~~~~~~~~~~~~~~~~^^^^^^^^^^^^^^^^^^^^^^^^^^^^^^^^^^^^^^^^
  File "/usr/local/lib/python3.13/site-packages/pymongo/mongo_client.py", line 1523, in _retryable_write
    return self._retry_with_session(retryable, func, s, bulk)
           ~~~~~~~~~~~~~~~~~~~~~~~~^^^^^^^^^^^^^^^^^^^^^^^^^^
  File "/usr/local/lib/python3.13/site-packages/pymongo/mongo_client.py", line 1421, in _retry_with_session
    return self._retry_internal(
           ~~~~~~~~~~~~~~~~~~~~^
        func=func,
        ^^^^^^^^^^
    ...<2 lines>...
        retryable=retryable,
        ^^^^^^^^^^^^^^^^^^^^
    )
    ^
  File "/usr/local/lib/python3.13/site-packages/pymongo/_csot.py", line 107, in csot_wrapper
    return func(self, *args, **kwargs)
  File "/usr/local/lib/python3.13/site-packages/pymongo/mongo_client.py", line 1462, in _retry_internal
    ).run()
      ~~~^^
  File "/usr/local/lib/python3.13/site-packages/pymongo/mongo_client.py", line 2315, in run
    return self._read() if self._is_read else self._write()
                                              ~~~~~~~~~~~^^
  File "/usr/local/lib/python3.13/site-packages/pymongo/mongo_client.py", line 2422, in _write
    return self._func(self._session, conn, self._retryable)  # type: ignore
           ~~~~~~~~~~^^^^^^^^^^^^^^^^^^^^^^^^^^^^^^^^^^^^^^
  File "/usr/local/lib/python3.13/site-packages/pymongo/collection.py", line 597, in _insert_command
    result = conn.command(
        self.__database.name,
    ...<5 lines>...
        retryable_write=retryable_write,
    )
  File "/usr/local/lib/python3.13/site-packages/pymongo/helpers.py", line 322, in inner
    return func(*args, **kwargs)
  File "/usr/local/lib/python3.13/site-packages/pymongo/pool.py", line 968, in command
    return command(
        self,
    ...<20 lines>...
        write_concern=write_concern,
    )
  File "/usr/local/lib/python3.13/site-packages/pymongo/network.py", line 192, in command
    helpers._check_command_response(
    ~~~~~~~~~~~~~~~~~~~~~~~~~~~~~~~^
        response_doc,
        ^^^^^^^^^^^^^
    ...<2 lines>...
        parse_write_concern_error=parse_write_concern_error,
        ^^^^^^^^^^^^^^^^^^^^^^^^^^^^^^^^^^^^^^^^^^^^^^^^^^^^
    )
    ^
  File "/usr/local/lib/python3.13/site-packages/pymongo/helpers.py", line 230, in _check_command_response
    raise OperationFailure(errmsg, code, response, max_wire_version)
pymongo.errors.OperationFailure: Error=13, Details='Response status code does not indicate success: Forbidden (403); Substatus: 3090; ActivityId: 69759397-d57f-4f10-990b-ce5bf03fefa8; Reason: ({"code":"Forbidden","message":"Message: {\"Errors\":[\"Database / Collection Count Quota exceeded: Maximum number of 'Collection' per account exceeded. Current configured quota 500. Learn more https://aka.ms/cosmosdbquota\"]}\r\nActivityId: 69759397-d57f-4f10-990b-ce5bf03fefa8, Request URI: /apps/ed986275-d647-4a6c-96b2-bdeb779dbf1a/services/1f793260-ffa6-4e29-9175-09562f6ec5cc/partitions/b878b1b3-a712-4fe0-9fc3-b4936168fb95/replicas/134031774034859638p, RequestStats: , SDK: Microsoft.Azure.Documents.Common/2.14.0"}
RequestUri: https://developer-platform-user-db-1-westus2.documents.azure.com/dbs/project_prj_yb56dlbv/colls;
RequestMethod: POST;
Header: Authorization Length: 80;
Header: x-ms-date Length: 29;
Header: x-ms-cosmos-sdk-supportedcapabilities Length: 1;
Header: x-ms-cosmos-insert-systempartitionkey Length: 4;
Header: x-ms-activity-id Length: 36;
Header: Cache-Control Length: 8;
Header: User-Agent Length: 143;
Header: x-ms-cosmos-apitype Length: 7;
Header: x-ms-version Length: 10;
Header: Accept Length: 16;
Header: x-ms-cosmos-compute-hop-count Length: 1;
Header: x-ms-gateway-use-mtls Length: 1;
Header: traceparent Length: 55;
Header: tracestate Length: 6;
, Request URI: /dbs/project_prj_yb56dlbv/colls, RequestStats: Microsoft.Azure.Cosmos.Tracing.TraceData.ClientSideRequestStatisticsTraceDatum, SDK: Windows/10.0.20348 cosmos-netstandard-sdk/3.18.0);, full error: {'ok': 0.0, 'errmsg': 'Error=13, Details=\'Response status code does not indicate success: Forbidden (403); Substatus: 3090; ActivityId: 69759397-d57f-4f10-990b-ce5bf03fefa8; Reason: ({"code":"Forbidden","message":"Message: {\\"Errors\\":[\\"Database / Collection Count Quota exceeded: Maximum number of \'Collection\' per account exceeded. Current configured quota 500. Learn more https://aka.ms/cosmosdbquota\\"]}\\r\\nActivityId: 69759397-d57f-4f10-990b-ce5bf03fefa8, Request URI: /apps/ed986275-d647-4a6c-96b2-bdeb779dbf1a/services/1f793260-ffa6-4e29-9175-09562f6ec5cc/partitions/b878b1b3-a712-4fe0-9fc3-b4936168fb95/replicas/134031774034859638p, RequestStats: , SDK: Microsoft.Azure.Documents.Common/2.14.0"}\r\nRequestUri: https://developer-platform-user-db-1-westus2.documents.azure.com/dbs/project_prj_yb56dlbv/colls;\r\nRequestMethod: POST;\r\nHeader: Authorization Length: 80;\r\nHeader: x-ms-date Length: 29;\r\nHeader: x-ms-cosmos-sdk-supportedcapabilities Length: 1;\r\nHeader: x-ms-cosmos-insert-systempartitionkey Length: 4;\r\nHeader: x-ms-activity-id Length: 36;\r\nHeader: Cache-Control Length: 8;\r\nHeader: User-Agent Length: 143;\r\nHeader: x-ms-cosmos-apitype Length: 7;\r\nHeader: x-ms-version Length: 10;\r\nHeader: Accept Length: 16;\r\nHeader: x-ms-cosmos-compute-hop-count Length: 1;\r\nHeader: x-ms-gateway-use-mtls Length: 1;\r\nHeader: traceparent Length: 55;\r\nHeader: tracestate Length: 6;\r\n, Request URI: /dbs/project_prj_yb56dlbv/colls, RequestStats: Microsoft.Azure.Cosmos.Tracing.TraceData.ClientSideRequestStatisticsTraceDatum, SDK: Windows/10.0.20348 cosmos-netstandard-sdk/3.18.0);', 'code': 13, 'codeName': 'Unauthorized'}
INFO:     172.20.0.1:53040 - "GET /hotels?max_price=800&limit=12 HTTP/1.1" 500 Internal Server Error
ERROR:    Exception in ASGI application
Traceback (most recent call last):
  File "/usr/local/lib/python3.13/site-packages/uvicorn/protocols/http/h11_impl.py", line 408, in run_asgi
    result = await app(  # type: ignore[func-returns-value]
             ^^^^^^^^^^^^^^^^^^^^^^^^^^^^^^^^^^^^^^^^^^^^^^
        self.scope, self.receive, self.send
        ^^^^^^^^^^^^^^^^^^^^^^^^^^^^^^^^^^^
    )
    ^
  File "/usr/local/lib/python3.13/site-packages/uvicorn/middleware/proxy_headers.py", line 84, in __call__
    return await self.app(scope, receive, send)
           ^^^^^^^^^^^^^^^^^^^^^^^^^^^^^^^^^^^^
  File "/usr/local/lib/python3.13/site-packages/fastapi/applications.py", line 1106, in __call__
    await super().__call__(scope, receive, send)
  File "/usr/local/lib/python3.13/site-packages/starlette/applications.py", line 122, in __call__
    await self.middleware_stack(scope, receive, send)
  File "/usr/local/lib/python3.13/site-packages/starlette/middleware/errors.py", line 184, in __call__
    raise exc
  File "/usr/local/lib/python3.13/site-packages/starlette/middleware/errors.py", line 162, in __call__
    await self.app(scope, receive, _send)
  File "/usr/local/lib/python3.13/site-packages/starlette/middleware/cors.py", line 91, in __call__
    await self.simple_response(scope, receive, send, request_headers=headers)
  File "/usr/local/lib/python3.13/site-packages/starlette/middleware/cors.py", line 146, in simple_response
    await self.app(scope, receive, send)
  File "/usr/local/lib/python3.13/site-packages/starlette/middleware/exceptions.py", line 79, in __call__
    raise exc
  File "/usr/local/lib/python3.13/site-packages/starlette/middleware/exceptions.py", line 68, in __call__
    await self.app(scope, receive, sender)
  File "/usr/local/lib/python3.13/site-packages/fastapi/middleware/asyncexitstack.py", line 20, in __call__
    raise e
  File "/usr/local/lib/python3.13/site-packages/fastapi/middleware/asyncexitstack.py", line 17, in __call__
    await self.app(scope, receive, send)
  File "/usr/local/lib/python3.13/site-packages/starlette/routing.py", line 718, in __call__
    await route.handle(scope, receive, send)
  File "/usr/local/lib/python3.13/site-packages/starlette/routing.py", line 276, in handle
    await self.app(scope, receive, send)
  File "/usr/local/lib/python3.13/site-packages/starlette/routing.py", line 66, in app
    response = await func(request)
               ^^^^^^^^^^^^^^^^^^^
  File "/usr/local/lib/python3.13/site-packages/fastapi/routing.py", line 274, in app
    raw_response = await run_endpoint_function(
                   ^^^^^^^^^^^^^^^^^^^^^^^^^^^^
        dependant=dependant, values=values, is_coroutine=is_coroutine
        ^^^^^^^^^^^^^^^^^^^^^^^^^^^^^^^^^^^^^^^^^^^^^^^^^^^^^^^^^^^^^
    )
    ^
  File "/usr/local/lib/python3.13/site-packages/fastapi/routing.py", line 193, in run_endpoint_function
    return await run_in_threadpool(dependant.call, **values)
           ^^^^^^^^^^^^^^^^^^^^^^^^^^^^^^^^^^^^^^^^^^^^^^^^^
  File "/usr/local/lib/python3.13/site-packages/starlette/concurrency.py", line 41, in run_in_threadpool
    return await anyio.to_thread.run_sync(func, *args)
           ^^^^^^^^^^^^^^^^^^^^^^^^^^^^^^^^^^^^^^^^^^^
  File "/usr/local/lib/python3.13/site-packages/anyio/to_thread.py", line 33, in run_sync
    return await get_asynclib().run_sync_in_worker_thread(
           ^^^^^^^^^^^^^^^^^^^^^^^^^^^^^^^^^^^^^^^^^^^^^^^
        func, *args, cancellable=cancellable, limiter=limiter
        ^^^^^^^^^^^^^^^^^^^^^^^^^^^^^^^^^^^^^^^^^^^^^^^^^^^^^
    )
    ^
  File "/usr/local/lib/python3.13/site-packages/anyio/_backends/_asyncio.py", line 877, in run_sync_in_worker_thread
    return await future
           ^^^^^^^^^^^^
  File "/usr/local/lib/python3.13/site-packages/anyio/_backends/_asyncio.py", line 807, in run
    result = context.run(func, *args)
  File "/home/workspace/main.py", line 155, in list_hotels
    _ensure_seed_hotels()
    ~~~~~~~~~~~~~~~~~~~^^
  File "/home/workspace/main.py", line 145, in _ensure_seed_hotels
    create_document("hotel", h)
    ~~~~~~~~~~~~~~~^^^^^^^^^^^^
  File "/home/workspace/database.py", line 43, in create_document
    result = db[collection_name].insert_one(data_dict)
  File "/usr/local/lib/python3.13/site-packages/pymongo/collection.py", line 669, in insert_one
    self._insert_one(
    ~~~~~~~~~~~~~~~~^
        document,
        ^^^^^^^^^
    ...<5 lines>...
        comment=comment,
        ^^^^^^^^^^^^^^^^
    ),
    ^
  File "/usr/local/lib/python3.13/site-packages/pymongo/collection.py", line 609, in _insert_one
    self.__database.client._retryable_write(acknowledged, _insert_command, session)
    ~~~~~~~~~~~~~~~~~~~~~~~~~~~~~~~~~~~~~~~^^^^^^^^^^^^^^^^^^^^^^^^^^^^^^^^^^^^^^^^
  File "/usr/local/lib/python3.13/site-packages/pymongo/mongo_client.py", line 1523, in _retryable_write
    return self._retry_with_session(retryable, func, s, bulk)
           ~~~~~~~~~~~~~~~~~~~~~~~~^^^^^^^^^^^^^^^^^^^^^^^^^^
  File "/usr/local/lib/python3.13/site-packages/pymongo/mongo_client.py", line 1421, in _retry_with_session
    return self._retry_internal(
           ~~~~~~~~~~~~~~~~~~~~^
        func=func,
        ^^^^^^^^^^
    ...<2 lines>...
        retryable=retryable,
        ^^^^^^^^^^^^^^^^^^^^
    )
    ^
  File "/usr/local/lib/python3.13/site-packages/pymongo/_csot.py", line 107, in csot_wrapper
    return func(self, *args, **kwargs)
  File "/usr/local/lib/python3.13/site-packages/pymongo/mongo_client.py", line 1462, in _retry_internal
    ).run()
      ~~~^^
  File "/usr/local/lib/python3.13/site-packages/pymongo/mongo_client.py", line 2315, in run
    return self._read() if self._is_read else self._write()
                                              ~~~~~~~~~~~^^
  File "/usr/local/lib/python3.13/site-packages/pymongo/mongo_client.py", line 2422, in _write
    return self._func(self._session, conn, self._retryable)  # type: ignore
           ~~~~~~~~~~^^^^^^^^^^^^^^^^^^^^^^^^^^^^^^^^^^^^^^
  File "/usr/local/lib/python3.13/site-packages/pymongo/collection.py", line 597, in _insert_command
    result = conn.command(
        self.__database.name,
    ...<5 lines>...
        retryable_write=retryable_write,
    )
  File "/usr/local/lib/python3.13/site-packages/pymongo/helpers.py", line 322, in inner
    return func(*args, **kwargs)
  File "/usr/local/lib/python3.13/site-packages/pymongo/pool.py", line 968, in command
    return command(
        self,
    ...<20 lines>...
        write_concern=write_concern,
    )
  File "/usr/local/lib/python3.13/site-packages/pymongo/network.py", line 192, in command
    helpers._check_command_response(
    ~~~~~~~~~~~~~~~~~~~~~~~~~~~~~~~^
        response_doc,
        ^^^^^^^^^^^^^
    ...<2 lines>...
        parse_write_concern_error=parse_write_concern_error,
        ^^^^^^^^^^^^^^^^^^^^^^^^^^^^^^^^^^^^^^^^^^^^^^^^^^^^
    )
    ^
  File "/usr/local/lib/python3.13/site-packages/pymongo/helpers.py", line 230, in _check_command_response
    raise OperationFailure(errmsg, code, response, max_wire_version)
pymongo.errors.OperationFailure: Error=13, Details='Response status code does not indicate success: Forbidden (403); Substatus: 3090; ActivityId: ebb257a4-d3c2-41a8-aa6c-dc9128aa1606; Reason: ({"code":"Forbidden","message":"Message: {\"Errors\":[\"Database / Collection Count Quota exceeded: Maximum number of 'Collection' per account exceeded. Current configured quota 500. Learn more https://aka.ms/cosmosdbquota\"]}\r\nActivityId: ebb257a4-d3c2-41a8-aa6c-dc9128aa1606, Request URI: /apps/ed986275-d647-4a6c-96b2-bdeb779dbf1a/services/1f793260-ffa6-4e29-9175-09562f6ec5cc/partitions/b878b1b3-a712-4fe0-9fc3-b4936168fb95/replicas/134031774034859638p, RequestStats: , SDK: Microsoft.Azure.Documents.Common/2.14.0"}
RequestUri: https://developer-platform-user-db-1-westus2.documents.azure.com/dbs/project_prj_yb56dlbv/colls;
RequestMethod: POST;
Header: Authorization Length: 82;
Header: x-ms-date Length: 29;
Header: x-ms-cosmos-sdk-supportedcapabilities Length: 1;
Header: x-ms-cosmos-insert-systempartitionkey Length: 4;
Header: x-ms-activity-id Length: 36;
Header: Cache-Control Length: 8;
Header: User-Agent Length: 143;
Header: x-ms-cosmos-apitype Length: 7;
Header: x-ms-version Length: 10;
Header: Accept Length: 16;
Header: x-ms-cosmos-compute-hop-count Length: 1;
Header: x-ms-gateway-use-mtls Length: 1;
Header: traceparent Length: 55;
Header: tracestate Length: 6;
, Request URI: /dbs/project_prj_yb56dlbv/colls, RequestStats: Microsoft.Azure.Cosmos.Tracing.TraceData.ClientSideRequestStatisticsTraceDatum, SDK: Windows/10.0.20348 cosmos-netstandard-sdk/3.18.0);, full error: {'ok': 0.0, 'errmsg': 'Error=13, Details=\'Response status code does not indicate success: Forbidden (403); Substatus: 3090; ActivityId: ebb257a4-d3c2-41a8-aa6c-dc9128aa1606; Reason: ({"code":"Forbidden","message":"Message: {\\"Errors\\":[\\"Database / Collection Count Quota exceeded: Maximum number of \'Collection\' per account exceeded. Current configured quota 500. Learn more https://aka.ms/cosmosdbquota\\"]}\\r\\nActivityId: ebb257a4-d3c2-41a8-aa6c-dc9128aa1606, Request URI: /apps/ed986275-d647-4a6c-96b2-bdeb779dbf1a/services/1f793260-ffa6-4e29-9175-09562f6ec5cc/partitions/b878b1b3-a712-4fe0-9fc3-b4936168fb95/replicas/134031774034859638p, RequestStats: , SDK: Microsoft.Azure.Documents.Common/2.14.0"}\r\nRequestUri: https://developer-platform-user-db-1-westus2.documents.azure.com/dbs/project_prj_yb56dlbv/colls;\r\nRequestMethod: POST;\r\nHeader: Authorization Length: 82;\r\nHeader: x-ms-date Length: 29;\r\nHeader: x-ms-cosmos-sdk-supportedcapabilities Length: 1;\r\nHeader: x-ms-cosmos-insert-systempartitionkey Length: 4;\r\nHeader: x-ms-activity-id Length: 36;\r\nHeader: Cache-Control Length: 8;\r\nHeader: User-Agent Length: 143;\r\nHeader: x-ms-cosmos-apitype Length: 7;\r\nHeader: x-ms-version Length: 10;\r\nHeader: Accept Length: 16;\r\nHeader: x-ms-cosmos-compute-hop-count Length: 1;\r\nHeader: x-ms-gateway-use-mtls Length: 1;\r\nHeader: traceparent Length: 55;\r\nHeader: tracestate Length: 6;\r\n, Request URI: /dbs/project_prj_yb56dlbv/colls, RequestStats: Microsoft.Azure.Cosmos.Tracing.TraceData.ClientSideRequestStatisticsTraceDatum, SDK: Windows/10.0.20348 cosmos-netstandard-sdk/3.18.0);', 'code': 13, 'codeName': 'Unauthorized'}
INFO:     172.20.0.1:34710 - "GET /hotels?max_price=800&limit=12 HTTP/1.1" 500 Internal Server Error
ERROR:    Exception in ASGI application
Traceback (most recent call last):
  File "/usr/local/lib/python3.13/site-packages/uvicorn/protocols/http/h11_impl.py", line 408, in run_asgi
    result = await app(  # type: ignore[func-returns-value]
             ^^^^^^^^^^^^^^^^^^^^^^^^^^^^^^^^^^^^^^^^^^^^^^
        self.scope, self.receive, self.send
        ^^^^^^^^^^^^^^^^^^^^^^^^^^^^^^^^^^^
    )
    ^
  File "/usr/local/lib/python3.13/site-packages/uvicorn/middleware/proxy_headers.py", line 84, in __call__
    return await self.app(scope, receive, send)
           ^^^^^^^^^^^^^^^^^^^^^^^^^^^^^^^^^^^^
  File "/usr/local/lib/python3.13/site-packages/fastapi/applications.py", line 1106, in __call__
    await super().__call__(scope, receive, send)
  File "/usr/local/lib/python3.13/site-packages/starlette/applications.py", line 122, in __call__
    await self.middleware_stack(scope, receive, send)
  File "/usr/local/lib/python3.13/site-packages/starlette/middleware/errors.py", line 184, in __call__
    raise exc
  File "/usr/local/lib/python3.13/site-packages/starlette/middleware/errors.py", line 162, in __call__
    await self.app(scope, receive, _send)
  File "/usr/local/lib/python3.13/site-packages/starlette/middleware/cors.py", line 91, in __call__
    await self.simple_response(scope, receive, send, request_headers=headers)
  File "/usr/local/lib/python3.13/site-packages/starlette/middleware/cors.py", line 146, in simple_response
    await self.app(scope, receive, send)
  File "/usr/local/lib/python3.13/site-packages/starlette/middleware/exceptions.py", line 79, in __call__
    raise exc
  File "/usr/local/lib/python3.13/site-packages/starlette/middleware/exceptions.py", line 68, in __call__
    await self.app(scope, receive, sender)
  File "/usr/local/lib/python3.13/site-packages/fastapi/middleware/asyncexitstack.py", line 20, in __call__
    raise e
  File "/usr/local/lib/python3.13/site-packages/fastapi/middleware/asyncexitstack.py", line 17, in __call__
    await self.app(scope, receive, send)
  File "/usr/local/lib/python3.13/site-packages/starlette/routing.py", line 718, in __call__
    await route.handle(scope, receive, send)
  File "/usr/local/lib/python3.13/site-packages/starlette/routing.py", line 276, in handle
    await self.app(scope, receive, send)
  File "/usr/local/lib/python3.13/site-packages/starlette/routing.py", line 66, in app
    response = await func(request)
               ^^^^^^^^^^^^^^^^^^^
  File "/usr/local/lib/python3.13/site-packages/fastapi/routing.py", line 274, in app
    raw_response = await run_endpoint_function(
                   ^^^^^^^^^^^^^^^^^^^^^^^^^^^^
        dependant=dependant, values=values, is_coroutine=is_coroutine
        ^^^^^^^^^^^^^^^^^^^^^^^^^^^^^^^^^^^^^^^^^^^^^^^^^^^^^^^^^^^^^
    )
    ^
  File "/usr/local/lib/python3.13/site-packages/fastapi/routing.py", line 193, in run_endpoint_function
    return await run_in_threadpool(dependant.call, **values)
           ^^^^^^^^^^^^^^^^^^^^^^^^^^^^^^^^^^^^^^^^^^^^^^^^^
  File "/usr/local/lib/python3.13/site-packages/starlette/concurrency.py", line 41, in run_in_threadpool
    return await anyio.to_thread.run_sync(func, *args)
           ^^^^^^^^^^^^^^^^^^^^^^^^^^^^^^^^^^^^^^^^^^^
  File "/usr/local/lib/python3.13/site-packages/anyio/to_thread.py", line 33, in run_sync
    return await get_asynclib().run_sync_in_worker_thread(
           ^^^^^^^^^^^^^^^^^^^^^^^^^^^^^^^^^^^^^^^^^^^^^^^
        func, *args, cancellable=cancellable, limiter=limiter
        ^^^^^^^^^^^^^^^^^^^^^^^^^^^^^^^^^^^^^^^^^^^^^^^^^^^^^
    )
    ^
  File "/usr/local/lib/python3.13/site-packages/anyio/_backends/_asyncio.py", line 877, in run_sync_in_worker_thread
    return await future
           ^^^^^^^^^^^^
  File "/usr/local/lib/python3.13/site-packages/anyio/_backends/_asyncio.py", line 807, in run
    result = context.run(func, *args)
  File "/home/workspace/main.py", line 155, in list_hotels
    _ensure_seed_hotels()
    ~~~~~~~~~~~~~~~~~~~^^
  File "/home/workspace/main.py", line 145, in _ensure_seed_hotels
    create_document("hotel", h)
    ~~~~~~~~~~~~~~~^^^^^^^^^^^^
  File "/home/workspace/database.py", line 43, in create_document
    result = db[collection_name].insert_one(data_dict)
  File "/usr/local/lib/python3.13/site-packages/pymongo/collection.py", line 669, in insert_one
    self._insert_one(
    ~~~~~~~~~~~~~~~~^
        document,
        ^^^^^^^^^
    ...<5 lines>...
        comment=comment,
        ^^^^^^^^^^^^^^^^
    ),
    ^
  File "/usr/local/lib/python3.13/site-packages/pymongo/collection.py", line 609, in _insert_one
    self.__database.client._retryable_write(acknowledged, _insert_command, session)
    ~~~~~~~~~~~~~~~~~~~~~~~~~~~~~~~~~~~~~~~^^^^^^^^^^^^^^^^^^^^^^^^^^^^^^^^^^^^^^^^
  File "/usr/local/lib/python3.13/site-packages/pymongo/mongo_client.py", line 1523, in _retryable_write
    return self._retry_with_session(retryable, func, s, bulk)
           ~~~~~~~~~~~~~~~~~~~~~~~~^^^^^^^^^^^^^^^^^^^^^^^^^^
  File "/usr/local/lib/python3.13/site-packages/pymongo/mongo_client.py", line 1421, in _retry_with_session
    return self._retry_internal(
           ~~~~~~~~~~~~~~~~~~~~^
        func=func,
        ^^^^^^^^^^
    ...<2 lines>...
        retryable=retryable,
        ^^^^^^^^^^^^^^^^^^^^
    )
    ^
  File "/usr/local/lib/python3.13/site-packages/pymongo/_csot.py", line 107, in csot_wrapper
    return func(self, *args, **kwargs)
  File "/usr/local/lib/python3.13/site-packages/pymongo/mongo_client.py", line 1462, in _retry_internal
    ).run()
      ~~~^^
  File "/usr/local/lib/python3.13/site-packages/pymongo/mongo_client.py", line 2315, in run
    return self._read() if self._is_read else self._write()
                                              ~~~~~~~~~~~^^
  File "/usr/local/lib/python3.13/site-packages/pymongo/mongo_client.py", line 2422, in _write
    return self._func(self._session, conn, self._retryable)  # type: ignore
           ~~~~~~~~~~^^^^^^^^^^^^^^^^^^^^^^^^^^^^^^^^^^^^^^
  File "/usr/local/lib/python3.13/site-packages/pymongo/collection.py", line 597, in _insert_command
    result = conn.command(
        self.__database.name,
    ...<5 lines>...
        retryable_write=retryable_write,
    )
  File "/usr/local/lib/python3.13/site-packages/pymongo/helpers.py", line 322, in inner
    return func(*args, **kwargs)
  File "/usr/local/lib/python3.13/site-packages/pymongo/pool.py", line 968, in command
    return command(
        self,
    ...<20 lines>...
        write_concern=write_concern,
    )
  File "/usr/local/lib/python3.13/site-packages/pymongo/network.py", line 192, in command
    helpers._check_command_response(
    ~~~~~~~~~~~~~~~~~~~~~~~~~~~~~~~^
        response_doc,
        ^^^^^^^^^^^^^
    ...<2 lines>...
        parse_write_concern_error=parse_write_concern_error,
        ^^^^^^^^^^^^^^^^^^^^^^^^^^^^^^^^^^^^^^^^^^^^^^^^^^^^
    )
    ^
  File "/usr/local/lib/python3.13/site-packages/pymongo/helpers.py", line 230, in _check_command_response
    raise OperationFailure(errmsg, code, response, max_wire_version)
pymongo.errors.OperationFailure: Error=13, Details='Response status code does not indicate success: Forbidden (403); Substatus: 3090; ActivityId: 87ce4e58-8f37-4fb8-a4df-68a202e69ded; Reason: ({"code":"Forbidden","message":"Message: {\"Errors\":[\"Database / Collection Count Quota exceeded: Maximum number of 'Collection' per account exceeded. Current configured quota 500. Learn more https://aka.ms/cosmosdbquota\"]}\r\nActivityId: 87ce4e58-8f37-4fb8-a4df-68a202e69ded, Request URI: /apps/ed986275-d647-4a6c-96b2-bdeb779dbf1a/services/1f793260-ffa6-4e29-9175-09562f6ec5cc/partitions/b878b1b3-a712-4fe0-9fc3-b4936168fb95/replicas/134031774034859638p, RequestStats: , SDK: Microsoft.Azure.Documents.Common/2.14.0"}
RequestUri: https://developer-platform-user-db-1-westus2.documents.azure.com/dbs/project_prj_yb56dlbv/colls;
RequestMethod: POST;
Header: Authorization Length: 80;
Header: x-ms-date Length: 29;
Header: x-ms-cosmos-sdk-supportedcapabilities Length: 1;
Header: x-ms-cosmos-insert-systempartitionkey Length: 4;
Header: x-ms-activity-id Length: 36;
Header: Cache-Control Length: 8;
Header: User-Agent Length: 143;
Header: x-ms-cosmos-apitype Length: 7;
Header: x-ms-version Length: 10;
Header: Accept Length: 16;
Header: x-ms-cosmos-compute-hop-count Length: 1;
Header: x-ms-gateway-use-mtls Length: 1;
Header: traceparent Length: 55;
Header: tracestate Length: 6;
, Request URI: /dbs/project_prj_yb56dlbv/colls, RequestStats: Microsoft.Azure.Cosmos.Tracing.TraceData.ClientSideRequestStatisticsTraceDatum, SDK: Windows/10.0.20348 cosmos-netstandard-sdk/3.18.0);, full error: {'ok': 0.0, 'errmsg': 'Error=13, Details=\'Response status code does not indicate success: Forbidden (403); Substatus: 3090; ActivityId: 87ce4e58-8f37-4fb8-a4df-68a202e69ded; Reason: ({"code":"Forbidden","message":"Message: {\\"Errors\\":[\\"Database / Collection Count Quota exceeded: Maximum number of \'Collection\' per account exceeded. Current configured quota 500. Learn more https://aka.ms/cosmosdbquota\\"]}\\r\\nActivityId: 87ce4e58-8f37-4fb8-a4df-68a202e69ded, Request URI: /apps/ed986275-d647-4a6c-96b2-bdeb779dbf1a/services/1f793260-ffa6-4e29-9175-09562f6ec5cc/partitions/b878b1b3-a712-4fe0-9fc3-b4936168fb95/replicas/134031774034859638p, RequestStats: , SDK: Microsoft.Azure.Documents.Common/2.14.0"}\r\nRequestUri: https://developer-platform-user-db-1-westus2.documents.azure.com/dbs/project_prj_yb56dlbv/colls;\r\nRequestMethod: POST;\r\nHeader: Authorization Length: 80;\r\nHeader: x-ms-date Length: 29;\r\nHeader: x-ms-cosmos-sdk-supportedcapabilities Length: 1;\r\nHeader: x-ms-cosmos-insert-systempartitionkey Length: 4;\r\nHeader: x-ms-activity-id Length: 36;\r\nHeader: Cache-Control Length: 8;\r\nHeader: User-Agent Length: 143;\r\nHeader: x-ms-cosmos-apitype Length: 7;\r\nHeader: x-ms-version Length: 10;\r\nHeader: Accept Length: 16;\r\nHeader: x-ms-cosmos-compute-hop-count Length: 1;\r\nHeader: x-ms-gateway-use-mtls Length: 1;\r\nHeader: traceparent Length: 55;\r\nHeader: tracestate Length: 6;\r\n, Request URI: /dbs/project_prj_yb56dlbv/colls, RequestStats: Microsoft.Azure.Cosmos.Tracing.TraceData.ClientSideRequestStatisticsTraceDatum, SDK: Windows/10.0.20348 cosmos-netstandard-sdk/3.18.0);', 'code': 13, 'codeName': 'Unauthorized'}
INFO:     172.20.0.1:34722 - "GET /hotels?max_price=800&limit=12 HTTP/1.1" 500 Internal Server Error
ERROR:    Exception in ASGI application
Traceback (most recent call last):
  File "/usr/local/lib/python3.13/site-packages/uvicorn/protocols/http/h11_impl.py", line 408, in run_asgi
    result = await app(  # type: ignore[func-returns-value]
             ^^^^^^^^^^^^^^^^^^^^^^^^^^^^^^^^^^^^^^^^^^^^^^
        self.scope, self.receive, self.send
        ^^^^^^^^^^^^^^^^^^^^^^^^^^^^^^^^^^^
    )
    ^
  File "/usr/local/lib/python3.13/site-packages/uvicorn/middleware/proxy_headers.py", line 84, in __call__
    return await self.app(scope, receive, send)
           ^^^^^^^^^^^^^^^^^^^^^^^^^^^^^^^^^^^^
  File "/usr/local/lib/python3.13/site-packages/fastapi/applications.py", line 1106, in __call__
    await super().__call__(scope, receive, send)
  File "/usr/local/lib/python3.13/site-packages/starlette/applications.py", line 122, in __call__
    await self.middleware_stack(scope, receive, send)
  File "/usr/local/lib/python3.13/site-packages/starlette/middleware/errors.py", line 184, in __call__
    raise exc
  File "/usr/local/lib/python3.13/site-packages/starlette/middleware/errors.py", line 162, in __call__
    await self.app(scope, receive, _send)
  File "/usr/local/lib/python3.13/site-packages/starlette/middleware/cors.py", line 91, in __call__
    await self.simple_response(scope, receive, send, request_headers=headers)
  File "/usr/local/lib/python3.13/site-packages/starlette/middleware/cors.py", line 146, in simple_response
    await self.app(scope, receive, send)
  File "/usr/local/lib/python3.13/site-packages/starlette/middleware/exceptions.py", line 79, in __call__
    raise exc
  File "/usr/local/lib/python3.13/site-packages/starlette/middleware/exceptions.py", line 68, in __call__
    await self.app(scope, receive, sender)
  File "/usr/local/lib/python3.13/site-packages/fastapi/middleware/asyncexitstack.py", line 20, in __call__
    raise e
  File "/usr/local/lib/python3.13/site-packages/fastapi/middleware/asyncexitstack.py", line 17, in __call__
    await self.app(scope, receive, send)
  File "/usr/local/lib/python3.13/site-packages/starlette/routing.py", line 718, in __call__
    await route.handle(scope, receive, send)
  File "/usr/local/lib/python3.13/site-packages/starlette/routing.py", line 276, in handle
    await self.app(scope, receive, send)
  File "/usr/local/lib/python3.13/site-packages/starlette/routing.py", line 66, in app
    response = await func(request)
               ^^^^^^^^^^^^^^^^^^^
  File "/usr/local/lib/python3.13/site-packages/fastapi/routing.py", line 274, in app
    raw_response = await run_endpoint_function(
                   ^^^^^^^^^^^^^^^^^^^^^^^^^^^^
        dependant=dependant, values=values, is_coroutine=is_coroutine
        ^^^^^^^^^^^^^^^^^^^^^^^^^^^^^^^^^^^^^^^^^^^^^^^^^^^^^^^^^^^^^
    )
    ^
  File "/usr/local/lib/python3.13/site-packages/fastapi/routing.py", line 193, in run_endpoint_function
    return await run_in_threadpool(dependant.call, **values)
           ^^^^^^^^^^^^^^^^^^^^^^^^^^^^^^^^^^^^^^^^^^^^^^^^^
  File "/usr/local/lib/python3.13/site-packages/starlette/concurrency.py", line 41, in run_in_threadpool
    return await anyio.to_thread.run_sync(func, *args)
           ^^^^^^^^^^^^^^^^^^^^^^^^^^^^^^^^^^^^^^^^^^^
  File "/usr/local/lib/python3.13/site-packages/anyio/to_thread.py", line 33, in run_sync
    return await get_asynclib().run_sync_in_worker_thread(
           ^^^^^^^^^^^^^^^^^^^^^^^^^^^^^^^^^^^^^^^^^^^^^^^
        func, *args, cancellable=cancellable, limiter=limiter
        ^^^^^^^^^^^^^^^^^^^^^^^^^^^^^^^^^^^^^^^^^^^^^^^^^^^^^
    )
    ^
  File "/usr/local/lib/python3.13/site-packages/anyio/_backends/_asyncio.py", line 877, in run_sync_in_worker_thread
    return await future
           ^^^^^^^^^^^^
  File "/usr/local/lib/python3.13/site-packages/anyio/_backends/_asyncio.py", line 807, in run
    result = context.run(func, *args)
  File "/home/workspace/main.py", line 155, in list_hotels
    _ensure_seed_hotels()
    ~~~~~~~~~~~~~~~~~~~^^
  File "/home/workspace/main.py", line 145, in _ensure_seed_hotels
    create_document("hotel", h)
    ~~~~~~~~~~~~~~~^^^^^^^^^^^^
  File "/home/workspace/database.py", line 43, in create_document
    result = db[collection_name].insert_one(data_dict)
  File "/usr/local/lib/python3.13/site-packages/pymongo/collection.py", line 669, in insert_one
    self._insert_one(
    ~~~~~~~~~~~~~~~~^
        document,
        ^^^^^^^^^
    ...<5 lines>...
        comment=comment,
        ^^^^^^^^^^^^^^^^
    ),
    ^
  File "/usr/local/lib/python3.13/site-packages/pymongo/collection.py", line 609, in _insert_one
    self.__database.client._retryable_write(acknowledged, _insert_command, session)
    ~~~~~~~~~~~~~~~~~~~~~~~~~~~~~~~~~~~~~~~^^^^^^^^^^^^^^^^^^^^^^^^^^^^^^^^^^^^^^^^
  File "/usr/local/lib/python3.13/site-packages/pymongo/mongo_client.py", line 1523, in _retryable_write
    return self._retry_with_session(retryable, func, s, bulk)
           ~~~~~~~~~~~~~~~~~~~~~~~~^^^^^^^^^^^^^^^^^^^^^^^^^^
  File "/usr/local/lib/python3.13/site-packages/pymongo/mongo_client.py", line 1421, in _retry_with_session
    return self._retry_internal(
           ~~~~~~~~~~~~~~~~~~~~^
        func=func,
        ^^^^^^^^^^
    ...<2 lines>...
        retryable=retryable,
        ^^^^^^^^^^^^^^^^^^^^
    )
    ^
  File "/usr/local/lib/python3.13/site-packages/pymongo/_csot.py", line 107, in csot_wrapper
    return func(self, *args, **kwargs)
  File "/usr/local/lib/python3.13/site-packages/pymongo/mongo_client.py", line 1462, in _retry_internal
    ).run()
      ~~~^^
  File "/usr/local/lib/python3.13/site-packages/pymongo/mongo_client.py", line 2315, in run
    return self._read() if self._is_read else self._write()
                                              ~~~~~~~~~~~^^
  File "/usr/local/lib/python3.13/site-packages/pymongo/mongo_client.py", line 2422, in _write
    return self._func(self._session, conn, self._retryable)  # type: ignore
           ~~~~~~~~~~^^^^^^^^^^^^^^^^^^^^^^^^^^^^^^^^^^^^^^
  File "/usr/local/lib/python3.13/site-packages/pymongo/collection.py", line 597, in _insert_command
    result = conn.command(
        self.__database.name,
    ...<5 lines>...
        retryable_write=retryable_write,
    )
  File "/usr/local/lib/python3.13/site-packages/pymongo/helpers.py", line 322, in inner
    return func(*args, **kwargs)
  File "/usr/local/lib/python3.13/site-packages/pymongo/pool.py", line 968, in command
    return command(
        self,
    ...<20 lines>...
        write_concern=write_concern,
    )
  File "/usr/local/lib/python3.13/site-packages/pymongo/network.py", line 192, in command
    helpers._check_command_response(
    ~~~~~~~~~~~~~~~~~~~~~~~~~~~~~~~^
        response_doc,
        ^^^^^^^^^^^^^
    ...<2 lines>...
        parse_write_concern_error=parse_write_concern_error,
        ^^^^^^^^^^^^^^^^^^^^^^^^^^^^^^^^^^^^^^^^^^^^^^^^^^^^
    )
    ^
  File "/usr/local/lib/python3.13/site-packages/pymongo/helpers.py", line 230, in _check_command_response
    raise OperationFailure(errmsg, code, response, max_wire_version)
pymongo.errors.OperationFailure: Error=13, Details='Response status code does not indicate success: Forbidden (403); Substatus: 3090; ActivityId: 8c074099-c870-4f4f-8dd3-5f0cdf1898e9; Reason: ({"code":"Forbidden","message":"Message: {\"Errors\":[\"Database / Collection Count Quota exceeded: Maximum number of 'Collection' per account exceeded. Current configured quota 500. Learn more https://aka.ms/cosmosdbquota\"]}\r\nActivityId: 8c074099-c870-4f4f-8dd3-5f0cdf1898e9, Request URI: /apps/ed986275-d647-4a6c-96b2-bdeb779dbf1a/services/1f793260-ffa6-4e29-9175-09562f6ec5cc/partitions/b878b1b3-a712-4fe0-9fc3-b4936168fb95/replicas/134031774034859638p, RequestStats: , SDK: Microsoft.Azure.Documents.Common/2.14.0"}
RequestUri: https://developer-platform-user-db-1-westus2.documents.azure.com/dbs/project_prj_yb56dlbv/colls;
RequestMethod: POST;
Header: Authorization Length: 80;
Header: x-ms-date Length: 29;
Header: x-ms-cosmos-sdk-supportedcapabilities Length: 1;
Header: x-ms-cosmos-insert-systempartitionkey Length: 4;
Header: x-ms-activity-id Length: 36;
Header: Cache-Control Length: 8;
Header: User-Agent Length: 143;
Header: x-ms-cosmos-apitype Length: 7;
Header: x-ms-version Length: 10;
Header: Accept Length: 16;
Header: x-ms-cosmos-compute-hop-count Length: 1;
Header: x-ms-gateway-use-mtls Length: 1;
Header: traceparent Length: 55;
Header: tracestate Length: 6;
, Request URI: /dbs/project_prj_yb56dlbv/colls, RequestStats: Microsoft.Azure.Cosmos.Tracing.TraceData.ClientSideRequestStatisticsTraceDatum, SDK: Windows/10.0.20348 cosmos-netstandard-sdk/3.18.0);, full error: {'ok': 0.0, 'errmsg': 'Error=13, Details=\'Response status code does not indicate success: Forbidden (403); Substatus: 3090; ActivityId: 8c074099-c870-4f4f-8dd3-5f0cdf1898e9; Reason: ({"code":"Forbidden","message":"Message: {\\"Errors\\":[\\"Database / Collection Count Quota exceeded: Maximum number of \'Collection\' per account exceeded. Current configured quota 500. Learn more https://aka.ms/cosmosdbquota\\"]}\\r\\nActivityId: 8c074099-c870-4f4f-8dd3-5f0cdf1898e9, Request URI: /apps/ed986275-d647-4a6c-96b2-bdeb779dbf1a/services/1f793260-ffa6-4e29-9175-09562f6ec5cc/partitions/b878b1b3-a712-4fe0-9fc3-b4936168fb95/replicas/134031774034859638p, RequestStats: , SDK: Microsoft.Azure.Documents.Common/2.14.0"}\r\nRequestUri: https://developer-platform-user-db-1-westus2.documents.azure.com/dbs/project_prj_yb56dlbv/colls;\r\nRequestMethod: POST;\r\nHeader: Authorization Length: 80;\r\nHeader: x-ms-date Length: 29;\r\nHeader: x-ms-cosmos-sdk-supportedcapabilities Length: 1;\r\nHeader: x-ms-cosmos-insert-systempartitionkey Length: 4;\r\nHeader: x-ms-activity-id Length: 36;\r\nHeader: Cache-Control Length: 8;\r\nHeader: User-Agent Length: 143;\r\nHeader: x-ms-cosmos-apitype Length: 7;\r\nHeader: x-ms-version Length: 10;\r\nHeader: Accept Length: 16;\r\nHeader: x-ms-cosmos-compute-hop-count Length: 1;\r\nHeader: x-ms-gateway-use-mtls Length: 1;\r\nHeader: traceparent Length: 55;\r\nHeader: tracestate Length: 6;\r\n, Request URI: /dbs/project_prj_yb56dlbv/colls, RequestStats: Microsoft.Azure.Cosmos.Tracing.TraceData.ClientSideRequestStatisticsTraceDatum, SDK: Windows/10.0.20348 cosmos-netstandard-sdk/3.18.0);', 'code': 13, 'codeName': 'Unauthorized'}
